File: Uploaded/BF1620.dat
[Header]
TITLE, default name
FILEOPENTIME,20102289.64,8/21/2017,3:53 PM
BYAPP, Resistivity, 2.1, 1.0
INFO, APPNAME, PPMS MultiVu Application, 1.5.11
INFO, , Sample1 Name
INFO, 1, Sample1 Cross Section
INFO, 1, Sample1 Length
INFO, Ohm-m, Sample1 Units
INFO, , Sample2 Name
INFO, 1, Sample2 Cross Section
INFO, 1, Sample2 Length
INFO, Ohm-m, Sample2 Units
INFO, , Sample3 Name
INFO, 1, Sample3 Cross Section
INFO, 1, Sample3 Length
INFO, Ohm-m, Sample3 Units
INFO, , Sample4 Name
INFO, 1, Sample4 Cross Section
INFO, 1, Sample4 Length
INFO, Ohm-m, Sample4 Units
FIELDGROUP, Resistivity,2,3,4,5,6,7,8,9,10,11,12,13,14,15,16,17,18,19,20,21,22,23,24,25,26,27,28,29,30,31,32,33,34,35,36,37,38,39,40,41
STARTUPGROUP, Resistivity
STARTUPAXIS, X, 2, LINEAR, AUTO
STARTUPAXIS, Y1, 7, LINEAR, AUTO
STARTUPAXIS, Y2, 9, LINEAR, AUTO
STARTUPAXIS, Y3, 11, LINEAR, AUTO
PLOT_APPEARANCE, ALL, HORZ_GRID_ON, VERT_GRID_ON, MARKERS_AND_LINES, ALL_LINES
DATATYPE, TIME, 2
DATATYPE, COMMENT, 1
[Data]
Comment,Time Stamp (sec),Status (code),Temperature (K),Magnetic Field (Oe),Sample Position (deg),Bridge 1 Resistivity (Ohm-m),Bridge 1 Excitation (uA),Bridge 2 Resistivity (Ohm-m),Bridge 2 Excitation (uA),Bridge 3 Resistivity (Ohm-m),Bridge 3 Excitation (uA),Bridge 4 Resistivity (Ohm-m),Bridge 4 Excitation (uA),Bridge 1 Std. Dev. (Ohm-m),Bridge 2 Std. Dev. (Ohm-m),Bridge 3 Std. Dev. (Ohm-m),Bridge 4 Std. Dev. (Ohm-m),Number of Readings,Bridge 1 Resistance (Ohms),Bridge 2 Resistance (Ohms),Bridge 3 Resistance (Ohms),Bridge 4 Resistance (Ohms),Signal 1 Vin (V),Signal 2 Vin (V),Digital Inputs (code),Drive 1 Iout (mA),Drive 1 Ipower (watts),Drive 2 Iout (mA),Drive 2 Ipower (watts),Pressure (),Map 20 (),Map 21 (),Map 22 (),Map 23 (),Map 24 (),Map 25 (),Map 26 (),Map 27 (),Map 28 (),Map 29 ()
,20102319.11,4417,300.005294799805,-0.252474719285965,0,0.381521766357422,50,,,-0.00383284372329712,50,,,5.49723103801639e-006,,1.11878727520205e-006,,25,381.521766357422,,-3.83284372329712,
,20102580.70,4417,300.00764465332,19999.114140625,0,0.381537770996094,50,,,-0.00387376766204834,50,,,7.36786329276816e-006,,6.41376086146343e-006,,25,381.537770996094,,-3.87376766204834,
,20102847.75,4417,300.00276184082,39999.193125,0,0.381609918212891,50,,,-0.00391304110527039,50,,,7.69098249292772e-006,,5.24806926027506e-006,,25,381.609918212891,,-3.91304110527039,
,20103115.39,4417,299.988891601563,59999.26328125,0,0.381625650634766,50,,,-0.00394583908081055,50,,,8.03777633732157e-006,,7.24375424061891e-006,,25,381.625650634766,,-3.94583908081055,
,20103327.05,4417,300.004043579102,65000.14171875,0,0.381620964355469,50,,,-0.00395407819747925,50,,,7.05671270110915e-006,,6.93771256330658e-006,,25,381.620964355469,,-3.95407819747925,
,20103595.48,4417,300.001052856445,44999.75921875,0,0.381631889648437,50,,,-0.00392208925247192,50,,,7.27670404956529e-006,,4.0710280913517e-006,,25,381.631889648437,,-3.92208925247192,
,20103861.16,4417,300.001892089844,24999.5653125,0,0.381639622802734,50,,,-0.00388490313529968,50,,,9.78023726928032e-006,,3.52850147589605e-006,,25,381.639622802734,,-3.88490313529968,
,20104124.48,4417,300.000259399414,4999.926640625,0,0.381631661376953,50,,,-0.0038441822719574,50,,,7.98530204793046e-006,,1.56281760547772e-006,,25,381.631661376953,,-3.8441822719574,
,20104387.16,4417,299.976745605469,-14999.17921875,0,0.381606771240234,50,,,-0.00380075889587402,50,,,6.43442078982301e-006,,3.61646878681156e-006,,25,381.606771240234,,-3.80075889587402,
,20104652.61,4417,300.008087158203,-34999.1740625,0,0.381658059082031,50,,,-0.00375460909843445,50,,,7.25220165274752e-006,,4.62631072596384e-006,,25,381.658059082031,,-3.75460909843445,
,20104920.31,4417,300.004302978516,-54999.30546875,0,0.381711278076172,50,,,-0.00370714864730835,50,,,7.84426550522505e-006,,4.0600262192092e-006,,25,381.711278076172,,-3.70714864730835,
,20105131.05,4417,300.005310058594,-69999.6140625,0,0.381776590576172,50,,,-0.00366852380752563,50,,,8.82214813762525e-006,,5.55757366372665e-006,,25,381.776590576172,,-3.66852380752563,
,20105401.47,4417,300.000549316406,-50000.208125,0,0.381738395996094,50,,,-0.00371929307937622,50,,,6.73844159657929e-006,,3.25870275850821e-006,,25,381.738395996094,,-3.71929307937622,
,20105667.08,4417,299.987442016602,-29999.61375,0,0.38168611328125,50,,,-0.00376691435813904,50,,,1.44442970826936e-005,,3.82647024736368e-006,,25,381.68611328125,,-3.76691435813904,
,20105932.44,4417,300.034561157227,-9999.5752734375,0,0.381669671630859,50,,,-0.00381326364517212,50,,,6.79963554696024e-006,,1.74031101465706e-006,,25,381.669671630859,,-3.81326364517212,
,20106297.31,4370,298.968154907227,-0.0243699997663498,0,0.381032022705078,50,,,-0.00382913331985474,50,,,8.97499054009746e-006,,8.96009325548889e-007,,25,381.032022705078,,-3.82913331985474,
,20106443.67,4374,294.823608398438,-0.0243699997663498,0,0.37864525390625,50,,,-0.00380898002624512,50,,,4.89178313466803e-005,,1.21400806553855e-006,,25,378.64525390625,,-3.80898002624512,
,20106584.59,4374,290.546340942383,-0.0243699997663498,0,0.376015892333984,50,,,-0.00378686772346497,50,,,8.69468652433917e-005,,1.39020361351728e-006,,25,376.015892333984,,-3.78686772346497,
,20106641.88,4370,283.133651733398,-0.0243699997663498,0,0.371918597412109,50,,,-0.00375245450019837,50,,,0.000252708057578135,,2.3187294722828e-006,,25,371.918597412109,,-3.75245450019836,
,20106698.64,4370,278.465148925781,-0.0243699997663498,0,0.368342781982422,50,,,-0.00372215386390686,50,,,0.000161917075787663,,1.71740378287189e-006,,25,368.342781982422,,-3.72215386390686,
,20106747.02,4370,274.491851806641,-0.0243699997663498,0,0.365593526611328,50,,,-0.00369875901222229,50,,,0.000143368478257339,,1.78172508480626e-006,,25,365.593526611328,,-3.69875901222229,
,20106810.17,4370,269.615158081055,-0.0243699997663498,0,0.362490411376953,50,,,-0.00367288594245911,50,,,0.0001250417450289,,1.55949127534682e-006,,25,362.490411376953,,-3.67288594245911,
,20106865.08,4370,264.286697387695,-0.0243699997663498,0,0.359318129882812,50,,,-0.00364582808494568,50,,,0.0002324369977165,,2.44868538417888e-006,,25,359.318129882813,,-3.64582808494568,
,20106925.55,4370,259.540100097656,-0.0243699997663498,0,0.355628583984375,50,,,-0.00364433459281922,50,,,0.000152706956962648,,1.99683809164692e-006,,25,355.628583984375,,-3.64433459281921,
,20106993.11,4374,254.638946533203,-0.0243699997663498,0,0.352464249267578,50,,,-0.00358134613037109,50,,,0.000110458732525644,,1.77379649812547e-006,,25,352.464249267578,,-3.58134613037109,
,20107053.19,4374,248.634300231934,-0.0243699997663498,0,0.348581364746094,50,,,-0.00355252973556519,50,,,0.000157760151561784,,1.78726221987262e-006,,25,348.581364746094,,-3.55252973556519,
,20107126.22,4374,243.415992736816,-0.0243699997663498,0,0.344984443359375,50,,,-0.00352263467788696,50,,,0.000122068821772238,,1.43754764584541e-006,,25,344.984443359375,,-3.52263467788696,
,20107191.47,4374,238.336952209473,-0.0243699997663498,0,0.341874924316406,50,,,-0.00349594066619873,50,,,0.000145083950639139,,1.90927960064317e-006,,25,341.874924316406,,-3.49594066619873,
,20107251.52,4370,232.508201599121,-0.0243699997663498,0,0.337832248535156,50,,,-0.0034615376663208,50,,,0.000142002633521309,,2.04149433779005e-006,,25,337.832248535156,,-3.4615376663208,
,20107329.08,4370,226.611053466797,-0.0243699997663498,0,0.334014464111328,50,,,-0.00342848198890686,50,,,0.000112726595016736,,1.61373443710152e-006,,25,334.014464111328,,-3.42848198890686,
,20107386.25,4370,221.172004699707,-0.0243699997663498,0,0.330959720458984,50,,,-0.00340182495117188,50,,,0.000229395322841828,,2.32312426293039e-006,,25,330.959720458984,,-3.40182495117188,
,20107443.25,4370,216.418045043945,-0.0243699997663498,0,0.327467999267578,50,,,-0.00337166567802429,50,,,0.000150227265632047,,2.34370406128692e-006,,25,327.467999267578,,-3.37166567802429,
,20107509.22,4374,211.698654174805,-0.0243699997663498,0,0.324457462158203,50,,,-0.00334606326103211,50,,,9.98652133402806e-005,,1.45755482028163e-006,,25,324.457462158203,,-3.3460632610321,
,20107574.30,4370,205.270500183105,-0.0243699997663498,0,0.320898306884766,50,,,-0.00331468963623047,50,,,0.000219063988778207,,2.52645036708731e-006,,25,320.898306884766,,-3.31468963623047,
,20107633.89,4370,200.571250915527,-0.0243699997663498,0,0.317554364013672,50,,,-0.00328587989807129,50,,,0.000135127907600714,,1.63773493521747e-006,,25,317.554364013672,,-3.28587989807129,
,20107686.64,4370,196.667053222656,-0.0243699997663498,0,0.315244644775391,50,,,-0.00326523502349854,50,,,0.000109674795077453,,1.46917762676336e-006,,25,315.244644775391,,-3.26523502349854,
,20107752.45,4374,191.231552124023,-0.0243699997663498,0,0.312336611328125,50,,,-0.0032399506855011,50,,,0.000196869748842521,,1.91051363612157e-006,,25,312.336611328125,,-3.2399506855011,
,20107814.31,4370,185.522804260254,-0.0243699997663498,0,0.308650101318359,50,,,-0.00320814541816711,50,,,0.00013848744082248,,1.51343687442032e-006,,25,308.650101318359,,-3.20814541816711,
,20107867.52,4370,181.493446350098,-0.0243699997663498,0,0.306318762207031,50,,,-0.00318720753669739,50,,,0.000113511212466703,,1.51469132298151e-006,,25,306.318762207031,,-3.18720753669739,
,20107931.28,4374,177.234954833984,-0.0243699997663498,0,0.304056037597656,50,,,-0.00316696753501892,50,,,0.000150869747947345,,1.70966443252233e-006,,25,304.056037597656,,-3.16696753501892,
,20107996.02,4370,170.473503112793,-0.0243699997663498,0,0.300150671386719,50,,,-0.00313247223854065,50,,,0.000119950923418217,,1.78621382522105e-006,,25,300.150671386719,,-3.13247223854065,
,20108044.05,4370,166.462348937988,-0.0243699997663498,0,0.297871419677734,50,,,-0.00311270546913147,50,,,0.000117440940976327,,1.98037441522201e-006,,25,297.871419677734,,-3.11270546913147,
,20108101.14,4374,162.739402770996,-0.0243699997663498,0,0.295871600341797,50,,,-0.00309460808753967,50,,,6.99505192226015e-005,,1.47952380444898e-006,,25,295.871600341797,,-3.09460808753967,
,20108165.98,4370,156.291847229004,-0.0243699997663498,0,0.292859261474609,50,,,-0.00306842439651489,50,,,0.000178896619447605,,2.04416052685047e-006,,25,292.859261474609,,-3.06842439651489,
,20108223.30,4370,151.445701599121,-0.0243699997663498,0,0.290079549560547,50,,,-0.00304333565711975,50,,,0.00011623738238098,,1.52800678939051e-006,,25,290.079549560547,,-3.04333565711975,
,20108274.16,4370,147.537048339844,-0.0243699997663498,0,0.288062502441406,50,,,-0.00302496380805969,50,,,8.02733241598069e-005,,1.54678129070047e-006,,25,288.062502441406,,-3.02496380805969,
,20108341.41,4374,143.358100891113,-0.0243699997663498,0,0.286127041015625,50,,,-0.00300750783920288,50,,,0.000101492788135819,,1.57864781360742e-006,,25,286.127041015625,,-3.00750783920288,
,20108400.50,4370,136.680152893066,-0.0243699997663498,0,0.2828563671875,50,,,-0.00297848069190979,50,,,9.81374248652307e-005,,1.46514686145243e-006,,25,282.8563671875,,-2.97848069190979,
,20108451.33,4370,132.523956298828,-0.0243699997663498,0,0.280864271240234,50,,,-0.00296054501533508,50,,,0.000101524760547016,,1.69311999867989e-006,,25,280.864271240234,,-2.96054501533508,
,20108503.36,4370,128.401756286621,-0.0243699997663498,0,0.279007951660156,50,,,-0.00294334085464477,50,,,7.719714500124e-005,,1.51027432164971e-006,,25,279.007951660156,,-2.94334085464478,
,20108564.73,4374,124.14725112915,-0.0243699997663498,0,0.277249110107422,50,,,-0.00292752985954285,50,,,0.000147076940101558,,2.17373542894008e-006,,25,277.249110107422,,-2.92752985954285,
,20108631.47,4370,117.457149505615,-0.0243699997663498,0,0.274142156982422,50,,,-0.00289961484909058,50,,,0.000101013079258003,,1.42840358693952e-006,,25,274.142156982422,,-2.89961484909058,
,20108679.45,4370,113.507900238037,-0.0243699997663498,0,0.272403400878906,50,,,-0.00288420147895813,50,,,9.34069240725938e-005,,1.2823438569105e-006,,25,272.403400878906,,-2.88420147895813,
,20108730.31,4370,109.649196624756,-0.0243699997663498,0,0.270782867431641,50,,,-0.0028692956161499,50,,,7.53568479483767e-005,,1.36263129049614e-006,,25,270.782867431641,,-2.8692956161499,
,20108797.28,4370,103.466800689697,-0.0243699997663498,0,0.268404826660156,50,,,-0.00284744627952576,50,,,0.0001236487065576,,1.42633654286774e-006,,25,268.404826660156,,-2.84744627952576,
,20108847.19,4370,99.536449432373,-0.0243699997663498,0,0.266667999267578,50,,,-0.00283190764427185,50,,,8.48564530018454e-005,,1.24571527377034e-006,,25,266.667999267578,,-2.83190764427185,
,20108895.27,4370,95.5192489624023,-0.0243699997663498,0,0.265091569824219,50,,,-0.0028166087436676,50,,,8.21689855069053e-005,,1.45708325641137e-006,,25,265.091569824219,,-2.8166087436676,
,20108943.45,4370,91.5021018981934,-0.0243699997663498,0,0.263575998535156,50,,,-0.00280136946678162,50,,,8.22603094732288e-005,,1.61486524587362e-006,,25,263.575998535156,,-2.80136946678162,
,20108991.67,4370,87.486499786377,-0.0243699997663498,0,0.262094157714844,50,,,-0.00278774320602417,50,,,7.83177614908695e-005,,1.37191973036115e-006,,25,262.094157714844,,-2.78774320602417,
,20109042.27,4370,83.704647064209,-0.0243699997663498,0,0.260691926269531,50,,,-0.00277422552108765,50,,,6.36145797620023e-005,,1.42468884642339e-006,,25,260.691926269531,,-2.77422552108765,
,20109111.55,4370,77.384449005127,-0.0243699997663498,0,0.258383576660156,50,,,-0.00275430860519409,50,,,0.000120118204927094,,1.30243454360147e-006,,25,258.383576660156,,-2.75430860519409,
,20109181.34,4370,72.478702545166,-0.0243699997663498,0,0.256409097900391,50,,,-0.002737667760849,50,,,7.22919778155946e-005,,1.5106299931054e-006,,25,256.409097900391,,-2.737667760849,
,20109254.45,4374,67.1892013549805,-0.0243699997663498,0,0.254578889160156,50,,,-0.00272093828201294,50,,,0.000140722789348622,,1.99508026797285e-006,,25,254.578889160156,,-2.72093828201294,
,20109325.73,4370,61.640100479126,-0.0243699997663498,0,0.252385119628906,50,,,-0.00270212164878845,50,,,4.78113174533816e-005,,1.420668826423e-006,,25,252.385119628906,,-2.70212164878845,
,20109408.61,4374,56.0370502471924,-0.0243699997663498,0,0.250676193237305,50,,,-0.0026836992263794,50,,,0.000142656186772686,,1.82112052899602e-006,,25,250.676193237305,,-2.68369922637939,
,20109471.17,4370,50.7798500061035,-0.0243699997663498,0,0.248784221191406,50,,,-0.00266762448310852,50,,,2.05246984510948e-005,,8.21879027862259e-007,,25,248.784221191406,,-2.66762448310852,
,20109540.61,4374,45.4151992797852,-0.0243699997663498,0,0.247333209838867,50,,,-0.00265725425720215,50,,,0.000184658228782059,,1.75937696886159e-006,,25,247.333209838867,,-2.65725425720215,
,20109627.44,4374,40.7018508911133,-0.0243699997663498,0,0.245828297119141,50,,,-0.00264442966461182,50,,,3.38294034539018e-005,,8.01511593392953e-007,,25,245.828297119141,,-2.64442966461182,
,20109723.53,4374,33.5660495758057,-0.0243699997663498,0,0.243999379882813,50,,,-0.00262787026405334,50,,,4.01474411023864e-005,,8.41589871892212e-007,,25,243.999379882812,,-2.62787026405334,
,20109831.56,4374,25.2912492752075,-0.0243699997663498,0,0.242279037475586,50,,,-0.00261452176094055,50,,,5.13878710773915e-005,,6.87363098927475e-007,,25,242.279037475586,,-2.61452176094055,
,20109954.30,4370,16.6226501464844,-0.0243699997663498,0,0.241027260131836,50,,,-0.00260652738571167,50,,,1.65317498071177e-005,,9.03919155843468e-007,,25,241.027260131836,,-2.60652738571167,
,20110010.53,4370,12.599100112915,-0.0243699997663498,0,0.240556415405273,50,,,-0.00260454679489136,50,,,2.91223739319424e-005,,6.94795816421133e-007,,25,240.556415405273,,-2.60454679489136,
,20110283.39,4417,20.009349822998,-0.125749957561493,0,0.241436524047852,50,,,-0.00260878887176514,50,,,6.30832897889018e-006,,8.85269509666145e-007,,25,241.436524047852,,-2.60878887176514,
,20110546.50,4417,19.9991006851196,19999.416484375,0,0.241441177978516,50,,,-0.00270149312019348,50,,,7.67689147412985e-006,,3.43707801052942e-006,,25,241.441177978516,,-2.70149312019348,
,20110813.25,4417,19.9999504089355,39999.28765625,0,0.241395084228516,50,,,-0.00279715711593628,50,,,7.66698004222495e-006,,4.73377098445435e-006,,25,241.395084228516,,-2.79715711593628,
,20111078.53,4417,19.9989500045776,59999.554375,0,0.241364848632812,50,,,-0.00289644073486328,50,,,6.30804793348312e-006,,2.70516198142095e-006,,25,241.364848632813,,-2.89644073486328,
,20111291.48,4421,20.0089998245239,64999.92171875,0,0.241349002685547,50,,,-0.00292098254203796,50,,,6.45803007274628e-006,,3.62507017407392e-006,,25,241.349002685547,,-2.92098254203796,
,20111558.19,4417,20.0006504058838,44999.68734375,0,0.241394943847656,50,,,-0.00282243134498596,50,,,8.46286505048511e-006,,5.47030491249809e-006,,25,241.394943847656,,-2.82243134498596,
,20111822.44,4417,19.9981508255005,25000.028671875,0,0.241418174438476,50,,,-0.00272520456314087,50,,,7.90387829032677e-006,,5.65508279310398e-006,,25,241.418174438477,,-2.72520456314087,
,20112086.30,4417,19.9983501434326,4999.79982421875,0,0.241439194335938,50,,,-0.00263082544326782,50,,,6.36355970834999e-006,,1.72761956386098e-006,,25,241.439194335937,,-2.63082544326782,
,20112352.92,4417,20.003399848938,-14999.3587109375,0,0.241428924560547,50,,,-0.0025394152545929,50,,,6.3374491402603e-006,,2.38303756114363e-006,,25,241.428924560547,,-2.5394152545929,
,20112618.25,4417,20.0013999938965,-34999.4471875,0,0.241414114379883,50,,,-0.00244755640029907,50,,,8.10306474526725e-006,,6.10421256712299e-006,,25,241.414114379883,,-2.44755640029907,
,20112883.33,4417,19.9988994598389,-54999.10359375,0,0.241382935180664,50,,,-0.00235242080688477,50,,,6.47762106823592e-006,,2.45561475908359e-006,,25,241.382935180664,,-2.35242080688477,
,20113094.25,4417,20.0009994506836,-69999.400625,0,0.241363266601562,50,,,-0.00228144169807434,50,,,8.66643291445086e-006,,3.32723076230265e-006,,25,241.363266601562,,-2.28144169807434,
,20113362.30,4417,19.9517507553101,-50000.37765625,0,0.241399740600586,50,,,-0.0023755961227417,50,,,7.91109405060024e-006,,4.68491595122752e-006,,25,241.399740600586,,-2.3755961227417,
,20113628.52,4417,20.0133495330811,-29999.871015625,0,0.241416165161133,50,,,-0.00247008134841919,50,,,7.69360657892341e-006,,6.59867844742995e-006,,25,241.416165161133,,-2.47008134841919,
,20113893.77,4417,19.9983997344971,-9999.594765625,0,0.241416870727539,50,,,-0.00256284733772278,50,,,7.19773421516586e-006,,2.33078211843403e-006,,25,241.416870727539,,-2.56284733772278,
,20114956.14,4370,11.5845003128052,69999.6015625,0,0.240317990722656,50,,,-0.0029331071472168,50,,,4.4459370976705e-005,,2.2385822587353e-006,,25,240.317990722656,,-2.9331071472168,
,20115003.94,4370,15.4892497062683,69999.6015625,0,0.24079244934082,50,,,-0.00293921062469482,50,,,2.28717173323776e-005,,2.96549311859627e-006,,25,240.79244934082,,-2.93921062469482,
,20115052.98,4370,19.524299621582,69999.6015625,0,0.241273579711914,50,,,-0.00294565454483032,50,,,3.14630801492109e-005,,3.14904951970811e-006,,25,241.273579711914,,-2.94565454483032,
,20115100.92,4370,23.4843502044678,69999.6015625,0,0.241853660888672,50,,,-0.00295172971725464,50,,,3.62984598219352e-005,,2.11528323434259e-006,,25,241.853660888672,,-2.95172971725464,
,20115148.53,4370,27.4690999984741,69999.6015625,0,0.242558714599609,50,,,-0.00295985363006592,50,,,4.02561571395324e-005,,3.86546567708288e-006,,25,242.558714599609,,-2.95985363006592,
,20115197.53,4370,31.510950088501,69999.6015625,0,0.243398090209961,50,,,-0.00296899118423462,50,,,4.90100805691169e-005,,2.73667134931393e-006,,25,243.398090209961,,-2.96899118423462,
,20115246.00,4370,35.5396499633789,69999.6015625,0,0.244347719116211,50,,,-0.0029786953830719,50,,,5.31385736585836e-005,,2.40127198135573e-006,,25,244.347719116211,,-2.9786953830719,
,20115293.95,4370,39.526050567627,69999.6015625,0,0.245359218139648,50,,,-0.00298977799415588,50,,,6.11436577397278e-005,,3.0041612510047e-006,,25,245.359218139648,,-2.98977799415588,
,20115341.63,4370,43.5162010192871,69999.6015625,0,0.246456527709961,50,,,-0.00300209216117859,50,,,5.67056387033413e-005,,3.41639313961161e-006,,25,246.456527709961,,-3.00209216117859,
,20115389.33,4370,47.4622497558594,69999.6015625,0,0.247593023071289,50,,,-0.00301405249595642,50,,,6.39883654879393e-005,,4.15020551471926e-006,,25,247.593023071289,,-3.01405249595642,
,20115437.28,4370,51.426549911499,69999.6015625,0,0.248789423217773,50,,,-0.00302626816749573,50,,,6.58655909539546e-005,,3.76678969037883e-006,,25,248.789423217773,,-3.02626816749573,
,20115485.69,4370,55.4823989868164,69999.6015625,0,0.250048088989258,50,,,-0.00304206569671631,50,,,6.88522936452889e-005,,4.43004562392162e-006,,25,250.048088989258,,-3.04206569671631,
,20115533.91,4370,59.4694004058838,69999.6015625,0,0.251351862182617,50,,,-0.00305629022598267,50,,,7.12569735409115e-005,,4.92580125737607e-006,,25,251.351862182617,,-3.05629022598267,
,20115582.06,4370,63.5020008087158,69999.6015625,0,0.252683115234375,50,,,-0.00307418329238892,50,,,7.06596556309779e-005,,5.49080482013493e-006,,25,252.683115234375,,-3.07418329238892,
,20115629.45,4370,67.4473495483398,69999.6015625,0,0.254023057861328,50,,,-0.0030827534198761,50,,,7.36353072392076e-005,,1.0524558882284e-005,,25,254.023057861328,,-3.0827534198761,
,20115677.48,4370,71.4365005493164,69999.6015625,0,0.255419927978516,50,,,-0.00309691709518433,50,,,8.16660875159545e-005,,5.25081413559611e-006,,25,255.419927978516,,-3.09691709518433,
,20115725.48,4370,75.434497833252,69999.6015625,0,0.256852904052734,50,,,-0.00309781203269958,50,,,7.78857169294911e-005,,6.4522075881912e-006,,25,256.852904052734,,-3.09781203269959,
,20115774.19,4370,79.4882507324219,69999.6015625,0,0.258328297119141,50,,,-0.00310463723182678,50,,,8.18957627302514e-005,,1.06825392113029e-005,,25,258.328297119141,,-3.10463723182678,
,20115822.50,4370,83.4839477539063,69999.6015625,0,0.259864012451172,50,,,-0.00311224645614624,50,,,8.1209135425801e-005,,1.12087288176574e-005,,25,259.864012451172,,-3.11224645614624,
,20115869.94,4370,87.4551010131836,69999.6015625,0,0.261367902832031,50,,,-0.00312314141273498,50,,,8.51490597711921e-005,,1.32013824938646e-005,,25,261.367902832031,,-3.12314141273499,
,20115918.31,4370,91.4967002868652,69999.6015625,0,0.26293125,50,,,-0.00312936359405518,50,,,8.86358169622158e-005,,1.28981849487474e-005,,25,262.93125,,-3.12936359405518,
,20115965.91,4370,95.4375991821289,69999.6015625,0,0.26445125,50,,,-0.00314069579124451,50,,,8.5309699224763e-005,,1.36245227084448e-005,,25,264.45125,,-3.14069579124451,
,20116014.36,4370,99.4770011901855,69999.6015625,0,0.266018480224609,50,,,-0.00315405366897583,50,,,8.52689015458407e-005,,1.21974645008335e-005,,25,266.018480224609,,-3.15405366897583,
,20116062.30,4370,103.518249511719,69999.6015625,0,0.267599532470703,50,,,-0.0031665546131134,50,,,8.7515046244729e-005,,7.46409279600719e-006,,25,267.599532470703,,-3.1665546131134,
,20116110.38,4370,107.505352020264,69999.6015625,0,0.269170908203125,50,,,-0.00317775955200195,50,,,8.84037930708607e-005,,8.01252045744499e-006,,25,269.170908203125,,-3.17775955200195,
,20116158.88,4370,111.537101745605,69999.6015625,0,0.270822962646484,50,,,-0.0031912989616394,50,,,8.92655815756126e-005,,9.60920625699527e-006,,25,270.822962646484,,-3.1912989616394,
,20116206.78,4370,115.524600982666,69999.6015625,0,0.272486369628906,50,,,-0.0032014245223999,50,,,9.29915646954804e-005,,7.79770129067089e-006,,25,272.486369628906,,-3.2014245223999,
,20116254.64,4370,119.515701293945,69999.6015625,0,0.274197399902344,50,,,-0.00321543264389038,50,,,9.48044323035181e-005,,9.33804054131115e-006,,25,274.197399902344,,-3.21543264389038,
,20116302.44,4370,123.502700805664,69999.6015625,0,0.275913031005859,50,,,-0.00322870666503906,50,,,9.69938163683469e-005,,9.34462365824767e-006,,25,275.913031005859,,-3.22870666503906,
,20116349.92,4370,127.456649780273,69999.6015625,0,0.277650220947266,50,,,-0.00324228436470032,50,,,0.000100185176231901,,1.01796114910722e-005,,25,277.650220947266,,-3.24228436470032,
,20116398.48,4370,131.506355285645,69999.6015625,0,0.279488106689453,50,,,-0.00325574265480042,50,,,9.79158946685598e-005,,1.01806627572932e-005,,25,279.488106689453,,-3.25574265480041,
,20116446.42,4370,135.49144744873,69999.6015625,0,0.281284527587891,50,,,-0.00326703812599182,50,,,0.000100881621401034,,1.43662580466628e-005,,25,281.284527587891,,-3.26703812599182,
,20116494.28,4370,139.497200012207,69999.6015625,0,0.283149288330078,50,,,-0.0032831854724884,50,,,0.00010364006962078,,1.22626339531792e-005,,25,283.149288330078,,-3.2831854724884,
,20116542.06,4370,143.476699829102,69999.6015625,0,0.285061057128906,50,,,-0.00329644938468933,50,,,0.000106444517269306,,1.01210698468023e-005,,25,285.061057128906,,-3.29644938468933,
,20116590.36,4370,147.526596069336,69999.6015625,0,0.287009327392578,50,,,-0.0033111669254303,50,,,0.00010445001590538,,1.26365752070712e-005,,25,287.009327392578,,-3.3111669254303,
,20116637.78,4370,151.463455200195,69999.6015625,0,0.288946168212891,50,,,-0.00332323886871338,50,,,0.000107601284142442,,1.54114199016149e-005,,25,288.946168212891,,-3.32323886871338,
,20116686.67,4370,155.522201538086,69999.6015625,0,0.290992561035156,50,,,-0.003337243309021,50,,,0.000111597996382554,,1.72688658591968e-005,,25,290.992561035156,,-3.337243309021,
,20116733.61,4370,159.433296203613,69999.6015625,0,0.293004621582031,50,,,-0.00335352189064026,50,,,0.000115518979537683,,1.49952315379561e-005,,25,293.004621582031,,-3.35352189064026,
,20116781.64,4370,163.444198608398,69999.6015625,0,0.295083823242188,50,,,-0.00336810863494873,50,,,0.000119393841814694,,2.24383986986075e-005,,25,295.083823242188,,-3.36810863494873,
,20116830.98,4370,167.535202026367,69999.6015625,0,0.297260874023437,50,,,-0.00338584202766418,50,,,0.000116430601607358,,1.53829788626036e-005,,25,297.260874023438,,-3.38584202766418,
,20116878.63,4370,171.53670501709,69999.6015625,0,0.299380502929687,50,,,-0.00340097396850586,50,,,0.000117177849958722,,2.09574038059968e-005,,25,299.380502929688,,-3.40097396850586,
,20116926.92,4370,175.539344787598,69999.6015625,0,0.301559317626953,50,,,-0.00341744293212891,50,,,0.000121588490152911,,3.07373030926186e-005,,25,301.559317626953,,-3.41744293212891,
,20116973.75,4370,179.444046020508,69999.6015625,0,0.303748287353516,50,,,-0.00343259442329407,50,,,0.000120092120198255,,2.64310145061356e-005,,25,303.748287353516,,-3.43259442329407,
,20117021.75,4370,183.452896118164,69999.6015625,0,0.306025883789063,50,,,-0.00344871014595032,50,,,0.000125161805159494,,2.36955024926613e-005,,25,306.025883789063,,-3.44871014595032,
,20117070.11,4370,187.483245849609,69999.6015625,0,0.308328302001953,50,,,-0.00346475544929504,50,,,0.000125523859537816,,2.95724500939187e-005,,25,308.328302001953,,-3.46475544929504,
,20117118.28,4370,191.488098144531,69999.6015625,0,0.310648848876953,50,,,-0.00348197788238525,50,,,0.000126104512737479,,3.17619290143671e-005,,25,310.648848876953,,-3.48197788238525,
,20117166.44,4370,195.520553588867,69999.6015625,0,0.313025316162109,50,,,-0.00350038063049317,50,,,0.000129695488351716,,3.17588668230046e-005,,25,313.025316162109,,-3.50038063049316,
,20117214.69,4370,199.523300170898,69999.6015625,0,0.315410325927734,50,,,-0.00351642561912537,50,,,0.000129277219995561,,6.93127235684974e-006,,25,315.410325927734,,-3.51642561912537,
,20117262.48,4370,203.514198303223,69999.6015625,0,0.317802012939453,50,,,-0.00353537732124329,50,,,0.000132667429942894,,7.33959231650255e-006,,25,317.802012939453,,-3.53537732124329,
,20117310.08,4370,207.466148376465,69999.6015625,0,0.320226507568359,50,,,-0.00355161479949951,50,,,0.000135752361732025,,6.16308437721342e-006,,25,320.226507568359,,-3.55161479949951,
,20117358.05,4370,211.468048095703,69999.6015625,0,0.322699715576172,50,,,-0.003569001121521,50,,,0.000134373153823527,,4.00691620572597e-006,,25,322.699715576172,,-3.569001121521,
,20117406.86,4370,215.531295776367,69999.6015625,0,0.325269847412109,50,,,-0.00358804300308228,50,,,0.000136612179379476,,6.79100649627445e-006,,25,325.269847412109,,-3.58804300308228,
,20117454.28,4370,219.51139831543,69999.6015625,0,0.327747403564453,50,,,-0.00360621321678162,50,,,0.000139186446766226,,5.41849611699532e-006,,25,327.747403564453,,-3.60621321678162,
,20117502.78,4370,223.548049926758,69999.6015625,0,0.330301851806641,50,,,-0.00362566087722778,50,,,0.000138600446963933,,1.12048138855818e-005,,25,330.301851806641,,-3.62566087722778,
,20117550.55,4370,227.510200500488,69999.6015625,0,0.332843654785156,50,,,-0.00364443873405457,50,,,0.000137158257975733,,5.44311874588543e-006,,25,332.843654785156,,-3.64443873405457,
,20117597.38,4370,231.457099914551,69999.6015625,0,0.335395080566406,50,,,-0.00366419034004211,50,,,0.000145776797770532,,3.56077141754556e-006,,25,335.395080566406,,-3.66419034004211,
,20117646.20,4370,235.516448974609,69999.6015625,0,0.338066433105469,50,,,-0.00368454048156738,50,,,0.00014878567632675,,4.17501850130228e-006,,25,338.066433105469,,-3.68454048156738,
,20117694.41,4370,239.496948242188,69999.6015625,0,0.340679290771484,50,,,-0.00370316285133362,50,,,0.000139592749720051,,3.599812701732e-006,,25,340.679290771484,,-3.70316285133362,
,20117742.63,4370,243.510650634766,69999.6015625,0,0.343315626220703,50,,,-0.00372061265945435,50,,,0.000149923034681711,,9.01781897420011e-006,,25,343.315626220703,,-3.72061265945435,
,20117790.03,4370,247.497001647949,69999.6015625,0,0.345903178710938,50,,,-0.00374130353927612,50,,,0.000140921155267174,,3.33669500935963e-006,,25,345.903178710937,,-3.74130353927612,
,20117838.31,4370,251.491943359375,69999.6015625,0,0.348508299560547,50,,,-0.0037632293510437,50,,,0.000140709266358551,,4.80503248136372e-006,,25,348.508299560547,,-3.7632293510437,
,20117886.25,4370,255.481399536133,69999.6015625,0,0.351137062988281,50,,,-0.00378353562355042,50,,,0.000139293138349202,,4.10973136550837e-006,,25,351.137062988281,,-3.78353562355042,
,20117935.11,4370,259.578857421875,69999.6015625,0,0.353840877685547,50,,,-0.00380406762123108,50,,,0.000141707693278645,,6.4412133892184e-006,,25,353.840877685547,,-3.80406762123108,
,20117981.97,4370,263.464202880859,69999.6015625,0,0.356400911865234,50,,,-0.00382145369529724,50,,,0.000141547272881779,,1.1531935441081e-005,,25,356.400911865234,,-3.82145369529724,
,20118029.63,4370,267.435195922852,69999.6015625,0,0.359029421386719,50,,,-0.00384178311347961,50,,,0.000144956394284125,,5.19411978052865e-006,,25,359.029421386719,,-3.84178311347961,
,20118077.86,4370,271.44775390625,69999.6015625,0,0.361719953613281,50,,,-0.00385735165596008,50,,,0.000143214206817947,,3.44789782543294e-006,,25,361.719953613281,,-3.85735165596008,
,20118126.41,4370,275.491104125977,69999.6015625,0,0.364352100830078,50,,,-0.00386965312004089,50,,,0.000141050655797103,,4.07943158208192e-006,,25,364.352100830078,,-3.86965312004089,
,20118174.16,4370,279.479644775391,69999.6015625,0,0.366991040039063,50,,,-0.003881189661026,50,,,0.000144882462500741,,5.94768822473085e-006,,25,366.991040039063,,-3.881189661026,
,20118221.80,4370,283.445709228516,69999.6015625,0,0.3696015234375,50,,,-0.00389041265487671,50,,,0.000144634382164792,,6.66002698240288e-006,,25,369.6015234375,,-3.89041265487671,
,20118270.86,4370,287.538711547852,69999.6015625,0,0.372299842529297,50,,,-0.00389010772705078,50,,,0.000145524347701311,,3.64487106075588e-006,,25,372.299842529297,,-3.89010772705078,
,20118318.70,4370,291.513259887695,69999.6015625,0,0.374886029052734,50,,,-0.0039054852771759,50,,,0.000142210643541597,,3.06230503706172e-006,,25,374.886029052734,,-3.9054852771759,
,20118366.64,4370,295.523849487305,69999.6015625,0,0.377484825439453,50,,,-0.00392071161270142,50,,,0.000143083297662995,,3.63537658582888e-006,,25,377.484825439453,,-3.92071161270142,
,20118414.53,4370,299.458953857422,69999.6015625,0,0.380046846923828,50,,,-0.00394306409835815,50,,,0.000136576932305063,,7.33955323277373e-006,,25,380.046846923828,,-3.94306409835815,
,20120193.03,4417,99.9958000183105,9999.2935546875,0,0.266533317871094,50,,,-0.00287673828125,50,,,7.9303573534582e-006,,1.38187760058443e-006,,25,266.533317871094,,-2.87673828125,
,20120460.81,4417,100.004447937012,29999.10375,0,0.266547689208984,50,,,-0.00297074802398682,50,,,1.21817533893944e-005,,3.18934784627372e-006,,25,266.547689208984,,-2.97074802398682,
,20120728.41,4417,100.002502441406,49999.37359375,0,0.266570588378906,50,,,-0.00306292053222656,50,,,6.99607534400679e-006,,2.14453919306836e-006,,25,266.570588378906,,-3.06292053222656,
,20120995.61,4417,99.998649597168,69999.5890625,0,0.266580300292969,50,,,-0.00315587717056274,50,,,9.20162162790863e-006,,8.89357081482948e-006,,25,266.580300292969,,-3.15587717056274,
,20121208.78,4417,99.9995498657227,55000.06609375,0,0.266577491455078,50,,,-0.00308572310447693,50,,,6.99225874587912e-006,,4.87195388059971e-006,,25,266.577491455078,,-3.08572310447693,
,20121474.23,4417,100.00085067749,34999.53859375,0,0.266551380615234,50,,,-0.00299379956245422,50,,,6.99600789947015e-006,,3.88983501170043e-006,,25,266.551380615234,,-2.99379956245422,
,20121741.66,4417,99.9980010986328,14999.7053515625,0,0.266537586669922,50,,,-0.00289928942680359,50,,,8.53337816238268e-006,,2.64290832554548e-006,,25,266.537586669922,,-2.89928942680359,
,20122004.22,4417,99.9997482299805,-4999.43619140625,0,0.266500631103516,50,,,-0.00280410387992859,50,,,8.15584399526433e-006,,1.87247402636582e-006,,25,266.500631103516,,-2.80410387992859,
,20122268.36,4417,100.002899169922,-24999.4909375,0,0.266553981933594,50,,,-0.0027087868309021,50,,,7.32147121353473e-006,,3.3170212418386e-006,,25,266.553981933594,,-2.7087868309021,
,20122533.97,4417,99.9998512268066,-44999.236875,0,0.266559547119141,50,,,-0.00261623670578003,50,,,8.09489638210603e-006,,6.18129696389808e-006,,25,266.559547119141,,-2.61623670578003,
,20122798.50,4417,100.000198364258,-64999.14046875,0,0.266593210449219,50,,,-0.00252369267463684,50,,,1.05832199508456e-005,,2.46299926411984e-006,,25,266.593210449219,,-2.52369267463684,
,20123806.05,4375,9.88490009307861,0.219330996274948,0,0.229853356933594,50,,,-0.00258982654571533,50,,,0.00972634045103777,,3.1145066588678e-005,,25,229.853356933594,,-2.58982654571533,
,20123945.45,4375,9.01030015945435,0.219330996274948,0,0.236724326782227,50,,,-0.00256934204101563,50,,,0.00114430993153727,,2.55794393151577e-006,,25,236.724326782227,,-2.56934204101562,
,20124207.19,4375,8.22325015068054,0.219330996274948,0,0.230870905151367,50,,,-0.00256927784919739,50,,,0.00232311218594275,,5.68014465205631e-006,,25,230.870905151367,,-2.56927784919739,
,20124568.33,4375,7.53690004348755,0.219330996274948,0,0.21561603515625,50,,,-0.00263320455551148,50,,,0.00214392731641425,,1.02102254767588e-005,,25,215.61603515625,,-2.63320455551147,
,20125735.47,4374,5.30830001831055,0.219330996274948,0,0.062851011672616,50,,,-0.00139304206566885,50,,,0.054290189607987,,0.00110119199832204,,25,62.851011672616,,-1.39304206566885,
,20125806.70,4374,2.35980010032654,0.219330996274948,0,-5.80152720795013e-008,50,,,1.2366412760457e-007,50,,,3.91792759247068e-007,,5.04658125267221e-007,,25,-5.80152720795013e-005,,0.00012366412760457,
,20126737.58,4370,4.44120001792908,-69999.2890625,0,0.206297014160156,50,,,-0.00224059105873108,50,,,0.00531693924612008,,1.77808217861228e-006,,25,206.297014160156,,-2.24059105873108,
,20126789.38,4370,8.51455020904541,-69999.2890625,0,0.238637246704102,50,,,-0.00228272450447082,50,,,0.000259438666341871,,2.14090229741299e-006,,25,238.637246704102,,-2.28272450447083,
,20126850.56,4370,13.5555000305176,-69999.2890625,0,0.240476605834961,50,,,-0.00229256500244141,50,,,2.32182370639645e-005,,2.10456500379891e-006,,25,240.476605834961,,-2.29256500244141,
,20126898.86,4370,17.5136003494263,-69999.2890625,0,0.240903138427734,50,,,-0.00229284512519836,50,,,2.50584130963908e-005,,1.97097028240942e-006,,25,240.903138427734,,-2.29284512519836,
,20126946.94,4370,21.4843997955322,-69999.2890625,0,0.241405282592774,50,,,-0.00229800182342529,50,,,3.19027625457532e-005,,2.07187441239969e-006,,25,241.405282592773,,-2.29800182342529,
,20126995.69,4370,25.5317001342773,-69999.2890625,0,0.242089207763672,50,,,-0.00230199402809143,50,,,3.9765814620522e-005,,1.89876029412335e-006,,25,242.089207763672,,-2.30199402809143,
,20127043.16,4370,29.5028505325317,-69999.2890625,0,0.242843599853516,50,,,-0.00230746913909912,50,,,4.90124694771025e-005,,3.34764268582017e-006,,25,242.843599853516,,-2.30746913909912,
,20127091.19,4370,33.4776515960693,-69999.2890625,0,0.243710711669922,50,,,-0.00231853989601135,50,,,5.12910854312122e-005,,2.93838063567744e-006,,25,243.710711669922,,-2.31853989601135,
,20127138.95,4370,37.4248504638672,-69999.2890625,0,0.244679959106445,50,,,-0.00232957427978516,50,,,5.60101131562574e-005,,1.49895597021244e-006,,25,244.679959106445,,-2.32957427978516,
,20127188.03,4370,41.5043506622314,-69999.2890625,0,0.245749839477539,50,,,-0.00234427947998047,50,,,5.73698347180944e-005,,2.17787160816289e-006,,25,245.749839477539,,-2.34427947998047,
,20127236.61,4370,45.5272006988525,-69999.2890625,0,0.246869159545899,50,,,-0.00235906789779663,50,,,6.39131552825927e-005,,1.94272688035391e-006,,25,246.869159545898,,-2.35906789779663,
,20127283.11,4370,49.426549911499,-69999.2890625,0,0.248026117553711,50,,,-0.00237754195213318,50,,,6.32584280225835e-005,,5.06061300863796e-006,,25,248.026117553711,,-2.37754195213318,
,20127332.47,4370,53.5089988708496,-69999.2890625,0,0.249283743286133,50,,,-0.00238651147842407,50,,,6.94906379427661e-005,,7.58968331988978e-006,,25,249.283743286133,,-2.38651147842407,
,20127380.58,4370,57.5214500427246,-69999.2890625,0,0.250559465942383,50,,,-0.00241286431312561,50,,,7.36673338293311e-005,,2.98506319796217e-006,,25,250.559465942383,,-2.41286431312561,
,20127428.19,4370,61.4987010955811,-69999.2890625,0,0.251878444213867,50,,,-0.0024409979057312,50,,,7.44136272680849e-005,,2.60850177485083e-006,,25,251.878444213867,,-2.4409979057312,
,20127476.44,4370,65.4960479736328,-69999.2890625,0,0.253214338989258,50,,,-0.00245928706169128,50,,,7.42926602572793e-005,,2.77785149998093e-006,,25,253.214338989258,,-2.45928706169128,
,20127524.53,4370,69.5116004943848,-69999.2890625,0,0.254585935058594,50,,,-0.00245196784973145,50,,,7.60397388669115e-005,,2.55727632392976e-005,,25,254.585935058594,,-2.45196784973145,
,20127573.08,4370,73.5409507751465,-69999.2890625,0,0.256025046386719,50,,,-0.00243016584396362,50,,,8.20648664299415e-005,,1.59675889825588e-005,,25,256.025046386719,,-2.43016584396362,
,20127621.28,4370,77.543098449707,-69999.2890625,0,0.257485657958984,50,,,-0.00246523880004883,50,,,8.23356811868871e-005,,3.15084383046242e-006,,25,257.485657958984,,-2.46523880004883,
,20127668.13,4370,81.4514007568359,-69999.2890625,0,0.258936551513672,50,,,-0.00243698115348816,50,,,8.35810290673389e-005,,2.79535423175817e-006,,25,258.936551513672,,-2.43698115348816,
,20127715.98,4370,85.4305000305176,-69999.2890625,0,0.260444008789063,50,,,-0.00245153524398804,50,,,8.35071325433299e-005,,4.69694252933143e-006,,25,260.444008789062,,-2.45153524398804,
,20127764.72,4370,89.5046501159668,-69999.2890625,0,0.262003759765625,50,,,-0.00246315170288086,50,,,8.11767286540946e-005,,4.66541393052571e-006,,25,262.003759765625,,-2.46315170288086,
,20127812.81,4370,93.525749206543,-69999.2890625,0,0.263569810791016,50,,,-0.00247442950248718,50,,,8.91147439589193e-005,,3.53041749685534e-006,,25,263.569810791016,,-2.47442950248718,
,20127859.95,4370,97.4489517211914,-69999.2890625,0,0.265078068847656,50,,,-0.00248796890258789,50,,,8.68552979763555e-005,,2.42900314969657e-006,,25,265.078068847656,,-2.48796890258789,
,20127908.52,4370,101.477550506592,-69999.2890625,0,0.266662634277344,50,,,-0.00250307323455811,50,,,7.70577431941714e-005,,2.47441562943439e-006,,25,266.662634277344,,-2.50307323455811,
,20127956.34,4370,105.485851287842,-69999.2890625,0,0.268227894287109,50,,,-0.00251877087593079,50,,,9.02646261539794e-005,,5.47015573243053e-006,,25,268.227894287109,,-2.51877087593079,
,20128003.95,4370,109.456001281738,-69999.2890625,0,0.269804482421875,50,,,-0.00253780926704407,50,,,9.46290345028686e-005,,7.40789719362167e-006,,25,269.804482421875,,-2.53780926704407,
,20128052.42,4370,113.474948883057,-69999.2890625,0,0.271479007568359,50,,,-0.00255553918838501,50,,,9.187090929038e-005,,3.55371472165494e-006,,25,271.479007568359,,-2.55553918838501,
,20128100.47,4370,117.48184967041,-69999.2890625,0,0.273181007080078,50,,,-0.00257372388839722,50,,,9.28142639656313e-005,,3.67384491629904e-006,,25,273.181007080078,,-2.57372388839722,
,20128148.23,4370,121.494750976563,-69999.2890625,0,0.274875070800781,50,,,-0.00259272694587708,50,,,9.6228658587521e-005,,4.69301003705049e-006,,25,274.875070800781,,-2.59272694587708,
,20128196.63,4370,125.503849029541,-69999.2890625,0,0.276635517578125,50,,,-0.00261464542388916,50,,,9.5158374003656e-005,,1.29309658303084e-005,,25,276.635517578125,,-2.61464542388916,
,20128244.58,4370,129.513153076172,-69999.2890625,0,0.278405262451172,50,,,-0.00263437993049622,50,,,9.86624594019173e-005,,8.82195066075729e-006,,25,278.405262451172,,-2.63437993049622,
,20128293.02,4370,133.526802062988,-69999.2890625,0,0.280231506347656,50,,,-0.0026530689907074,50,,,0.000101874888935235,,5.11982750527547e-006,,25,280.231506347656,,-2.6530689907074,
,20128340.00,4370,137.464401245117,-69999.2890625,0,0.282053448486328,50,,,-0.00267365609169006,50,,,0.000100203718440996,,3.01557140197874e-006,,25,282.053448486328,,-2.67365609169006,
,20128388.05,4370,141.452751159668,-69999.2890625,0,0.283922602539062,50,,,-0.00269404897689819,50,,,0.000106374760836339,,3.61913509352431e-006,,25,283.922602539063,,-2.69404897689819,
,20128436.03,4370,145.472801208496,-69999.2890625,0,0.285871207275391,50,,,-0.00271711060523987,50,,,0.000100920498466723,,1.24007926238467e-005,,25,285.871207275391,,-2.71711060523987,
,20128483.91,4370,149.46395111084,-69999.2890625,0,0.287798891601562,50,,,-0.00273777665138245,50,,,0.00011053936781279,,8.2897044983828e-006,,25,287.798891601563,,-2.73777665138245,
,20128532.41,4370,153.478797912598,-69999.2890625,0,0.289798237304688,50,,,-0.00275975894927979,50,,,0.000107957143064934,,4.5317303242059e-006,,25,289.798237304688,,-2.75975894927979,
,20128579.84,4370,157.444145202637,-69999.2890625,0,0.291801345214844,50,,,-0.00278145705223083,50,,,0.000108060854953336,,4.78096912073172e-006,,25,291.801345214844,,-2.78145705223083,
,20128629.03,4370,161.53475189209,-69999.2890625,0,0.293893288574219,50,,,-0.00280538710594177,50,,,0.000113293614425149,,2.8218815506057e-006,,25,293.893288574219,,-2.80538710594177,
,20128676.91,4370,165.531646728516,-69999.2890625,0,0.296002915039063,50,,,-0.00282854566574097,50,,,0.000117616725160637,,9.20425451238371e-006,,25,296.002915039062,,-2.82854566574097,
,20128724.88,4370,169.519950866699,-69999.2890625,0,0.298129194335937,50,,,-0.00285051342010498,50,,,0.000116379259484389,,5.06006525005929e-006,,25,298.129194335937,,-2.85051342010498,
,20128772.63,4370,173.486999511719,-69999.2890625,0,0.300283193359375,50,,,-0.00287580629348755,50,,,0.000116610134082052,,4.3713185567823e-006,,25,300.283193359375,,-2.87580629348755,
,20128820.50,4370,177.472297668457,-69999.2890625,0,0.302498333740234,50,,,-0.0028997779750824,50,,,0.000120293528595006,,4.09648080374727e-006,,25,302.498333740234,,-2.8997779750824,
,20128868.50,4370,181.474700927734,-69999.2890625,0,0.304712977294922,50,,,-0.00292385157585144,50,,,0.000121355705050217,,4.68266711456314e-006,,25,304.712977294922,,-2.92385157585144,
,20128917.03,4370,185.538307189941,-69999.2890625,0,0.307039447021484,50,,,-0.00295040329933167,50,,,0.000130391475511786,,6.27047194277551e-006,,25,307.039447021484,,-2.95040329933166,
,20128964.88,4370,189.52855682373,-69999.2890625,0,0.309343151855469,50,,,-0.00297525131225586,50,,,0.000125383985157789,,6.98101844786925e-006,,25,309.343151855469,,-2.97525131225586,
,20129012.89,4370,193.508903503418,-69999.2890625,0,0.311672459716797,50,,,-0.00300051087379456,50,,,0.000126060525057548,,3.65937176371226e-006,,25,311.672459716797,,-3.00051087379456,
,20129072.59,4370,198.483551025391,-69999.2890625,0,0.314591566162109,50,,,-0.00303358748435974,50,,,0.000129901232148774,,4.23518644228013e-006,,25,314.591566162109,,-3.03358748435974,
,20129120.25,4370,202.456199645996,-69999.2890625,0,0.317023342285156,50,,,-0.00305969875335693,50,,,0.000131030500129721,,4.53299419099503e-006,,25,317.023342285156,,-3.05969875335693,
,20129168.25,4370,206.465354919434,-69999.2890625,0,0.319412965087891,50,,,-0.00308749596595764,50,,,0.000129916814892566,,5.09034068649154e-006,,25,319.412965087891,,-3.08749596595764,
,20129216.47,4370,210.488899230957,-69999.2890625,0,0.321908016357422,50,,,-0.00311327961921692,50,,,0.000132793996663638,,9.79688844962479e-006,,25,321.908016357422,,-3.11327961921692,
,20129263.98,4370,214.461151123047,-69999.2890625,0,0.324381483154297,50,,,-0.0031391708946228,50,,,0.000138711241090528,,1.09257703841349e-005,,25,324.381483154297,,-3.1391708946228,
,20129313.31,4370,218.552345275879,-69999.2890625,0,0.326956286621094,50,,,-0.00316824751853943,50,,,0.000139352617466521,,3.92940295798047e-006,,25,326.956286621094,,-3.16824751853943,
,20129360.28,4370,222.473648071289,-69999.2890625,0,0.329450476074219,50,,,-0.00319685617446899,50,,,0.000140142966147276,,3.90382504329639e-006,,25,329.450476074219,,-3.19685617446899,
,20129408.30,4370,226.458549499512,-69999.2890625,0,0.331982818603516,50,,,-0.00322640211105347,50,,,0.00014097736217874,,3.63459337165522e-006,,25,331.982818603516,,-3.22640211105347,
,20129456.38,4370,230.489845275879,-69999.2890625,0,0.334582888183594,50,,,-0.00325253087997437,50,,,0.000142086628770464,,1.45251621414769e-005,,25,334.582888183594,,-3.25253087997437,
,20129504.50,4370,234.488143920898,-69999.2890625,0,0.337198298339844,50,,,-0.00328061265945435,50,,,0.000145686086426756,,1.25894343699144e-005,,25,337.198298339844,,-3.28061265945435,
,20129564.05,4370,239.45849609375,-69999.2890625,0,0.340468765869141,50,,,-0.00331936040878296,50,,,0.000141204081569637,,4.89512040362102e-006,,25,340.468765869141,,-3.31936040878296,
,20129624.70,4370,244.506652832031,-69999.2890625,0,0.343730870361328,50,,,-0.00335452936172485,50,,,0.000140403656171701,,1.61725034849875e-005,,25,343.730870361328,,-3.35452936172485,
,20129672.86,4370,248.541000366211,-69999.2890625,0,0.346356275634766,50,,,-0.00338374081611633,50,,,0.000142966520843896,,3.39994506753971e-006,,25,346.356275634766,,-3.38374081611633,
,20129720.06,4370,252.455947875977,-69999.2890625,0,0.348959901123047,50,,,-0.00341566995620728,50,,,0.000144553443422251,,1.18863189245158e-005,,25,348.959901123047,,-3.41566995620728,
,20129768.75,4370,256.500549316406,-69999.2890625,0,0.351647747802734,50,,,-0.00344617211341858,50,,,0.000144355642842196,,5.26768080297293e-006,,25,351.647747802734,,-3.44617211341858,
,20129816.75,4370,260.500457763672,-69999.2890625,0,0.354281895751953,50,,,-0.00347921112060547,50,,,0.000145392054760334,,3.62004052532404e-006,,25,354.281895751953,,-3.47921112060547,
,20129864.64,4370,264.463653564453,-69999.2890625,0,0.356936931152344,50,,,-0.0035046918964386,50,,,0.000141102587097098,,3.59129138032081e-006,,25,356.936931152344,,-3.5046918964386,
,20129912.78,4370,268.511749267578,-69999.2890625,0,0.359605981445313,50,,,-0.00352779952049255,50,,,0.000143380625316084,,4.31791272062753e-006,,25,359.605981445313,,-3.52779952049255,
,20129960.67,4370,272.470596313477,-69999.2890625,0,0.362238449707031,50,,,-0.00353753149032593,50,,,0.000146200045168868,,4.93489591167767e-006,,25,362.238449707031,,-3.53753149032593,
,20130008.42,4370,276.435699462891,-69999.2890625,0,0.364888184814453,50,,,-0.00350859574317932,50,,,0.000141897639334132,,1.27579688360355e-005,,25,364.888184814453,,-3.50859574317932,
,20130055.94,4370,280.428009033203,-69999.2890625,0,0.367508731689453,50,,,-0.00351606612205505,50,,,0.000145344345204783,,3.03973714046398e-005,,25,367.508731689453,,-3.51606612205505,
,20130104.30,4370,284.47380065918,-69999.2890625,0,0.370172183837891,50,,,-0.00350868378639221,50,,,0.000138424140409517,,4.62844797714588e-006,,25,370.172183837891,,-3.50868378639221,
,20130152.38,4370,288.472457885742,-69999.2890625,0,0.372816356201172,50,,,-0.00351923037528992,50,,,0.000141050379029476,,5.21700357649108e-006,,25,372.816356201172,,-3.51923037528992,
,20130201.05,4370,292.535202026367,-69999.2890625,0,0.375471694335938,50,,,-0.00354897203445435,50,,,0.000143199816004628,,6.1166864978298e-006,,25,375.471694335938,,-3.54897203445435,
,20130248.03,4370,296.471588134766,-69999.2890625,0,0.378044421386719,50,,,-0.0035848920249939,50,,,0.000145204612694784,,1.36290258483127e-005,,25,378.044421386719,,-3.5848920249939,
,20130299.70,4370,300.152496337891,-69999.2890625,0,0.380668675537109,50,,,-0.00361719264030457,50,,,9.42652213834226e-005,,4.07122370767568e-006,,25,380.668675537109,,-3.61719264030457,